{"name": "test_get_degree", "status": "passed", "start": 1699705534865, "stop": 1699705536869, "uuid": "515c93d6-b187-49d2-b267-384b549203b8", "historyId": "468aec060832385e17c3cd48d0f7e55f", "testCaseId": "468aec060832385e17c3cd48d0f7e55f", "fullName": "test_task2#test_get_degree", "labels": [{"name": "story", "value": "Задача 2. Асинхронный тест функции, возвращающей промис с ожидаемым исключением"}, {"name": "tag", "value": "asyncio"}, {"name": "suite", "value": "test_task2"}, {"name": "host", "value": "alexMBP-14.local"}, {"name": "thread", "value": "25041-MainThread"}, {"name": "framework", "value": "pytest"}, {"name": "language", "value": "cpython3"}, {"name": "package", "value": "test_task2"}]}